Workbook

Sheet API Calls
A1: # | B1: Scenario | C1: Time (UTC) | D1: Method | E1: Endpoint | F1: URL | G1: Payload | H1: Status Code | I1: Status Text | J1: Response | K1: Duration (ms)
A2: 1 | B2: 1. Login › Login with valid credentials lands on dashboard | C2: 2026-10-07 08:38:34.761 | D2: POST | E2: www.googleapis.com/identitytoolkit/v3/relyingparty/verifyPassword | F2: https://www.googleapis.com/identitytoolkit/v3/relyingparty/verifyPassword?key=AIzaSyDIM4lfYVaidv9qYmzRhvf5NPmgwQcU_4s | G2: { "email": "softwaredco@sunmobility.com", "password": "***REDACTED***", "returnSecureToken": true } | H2: 200 | J2: { "kind": "identitytoolkit#VerifyPasswordResponse", "localId": "1bwyuxWbg7ZbHhHJM4LXRPZ0WPw2", "email": "softwaredco@sunmobility.com", "displayName": "", "idToken": "***REDACTED***", "registered": true, "refreshToken": "***REDACTED***", "expiresIn": "3600" } | K2: 1231
A3: 2 | B3: 1. Login › Login with valid credentials lands on dashboard | C3: 2026-10-07 08:38:35.974 | D3: POST | E3: www.googleapis.com/identitytoolkit/v3/relyingparty/getAccountInfo | F3: https://www.googleapis.com/identitytoolkit/v3/relyingparty/getAccountInfo?key=AIzaSyDIM4lfYVaidv9qYmzRhvf5NPmgwQcU_4s | G3: { "idToken": "***REDACTED***" } | H3: 200 | J3: { "kind": "identitytoolkit#GetAccountInfoResponse", "users": [ { "localId": "1bwyuxWbg7ZbHhHJM4LXRPZ0WPw2", "email": "softwaredco@sunmobility.com", "passwordHash": "UkVEQUNURUQ=", "emailVerified": false, "passwordUpdatedAt": 1714840202414, "providerUserInfo": [ { "providerId": "password", "federatedId": "softwaredco@sunmobility.com", "email": "softwaredco@sunmobility.com", "rawId": "softwaredco@sunmobility.com" } ], "validSince": "1714840202", "disabled": false, "lastLoginAt": "1791362315801", "createdAt": "1714840202414", "lastRefreshAt": "2026-10-07T08:38:35.801Z" } ] } | K3: 551
A4: 3 | B4: 1. Login › Login with valid credentials lands on dashboard | C4: 2026-10-07 08:38:36.536 | D4: POST | E4: smartnetwork.azure-api.net/smauth/api/v1/OAuth/ThirdPartyAuthentication | F4: https://smartnetwork.azure-api.net/smauth/api/v1/OAuth/ThirdPartyAuthentication | G4: { "email": "softwaredco@sunmobility.com", "password": "***REDACTED***", "returnSecureToken": true } | H4: 200 | I4: OK | J4: { "version": "1.0.0.0", "statusCode": 200, "message": "<JWT redacted>" } | K4: 570
A5: 4 | B5: 1. Login › Login with valid credentials lands on dashboard | C5: 2026-10-07 08:38:37.109 | D5: GET | E5: smartnetwork.azure-api.net/partner-stage/api/v1/GetUserByEmail | F5: https://smartnetwork.azure-api.net/partner-stage/api/v1/GetUserByEmail?userEmail=softwaredco@sunmobility.com | H5: 200 | I5: OK | J5: { "status": 200, "data": { "userName": "RBAC Admin", "userEmail": "softwaredco@sunmobility.com", "userMobileNumber": "9845213813", "countryCode": "91", "userRole": "admin", "partnerId": "SUNMP00000121", "isActive": true, "isKeyFobMapped": false, "userId": "SUNMU00000370", "userType": "software", "createdAt": "1640240582", "lastModifiedAt": "1640240582", "createdUser": "Sun Mobility", "lastUpdatedUser": "Sun Mobility", "Key": "***REDACTED***", "legalEntityGuid": [ "c2b2bca1-019a-4757-ba37-9d9f5b30826a", "220c9382-d721-46db-9681-39bb9fff1511" ], "organizationName": "Sun Mobility Pvt Ltd", "brandName": "sun mobility" } } | K5: 3351
A6: 5 | B6: 1. Login › Login with invalid password shows error | C6: 2026-10-07 08:38:56.904 | D6: POST | E6: www.googleapis.com/identitytoolkit/v3/relyingparty/verifyPassword | F6: https://www.googleapis.com/identitytoolkit/v3/relyingparty/verifyPassword?key=AIzaSyDIM4lfYVaidv9qYmzRhvf5NPmgwQcU_4s | G6: { "email": "softwaredco@sunmobility.com", "password": "***REDACTED***", "returnSecureToken": true } | H6: 400 | J6: { "error": { "code": 400, "message": "INVALID_PASSWORD", "errors": [ { "message": "INVALID_PASSWORD", "domain": "global", "reason": "invalid" } ] } } | K6: 627
A7: 6 | B7: 2. Application › Applications grid loads with expected columns | C7: 2026-10-07 08:39:15.924 | D7: POST | E7: www.googleapis.com/identitytoolkit/v3/relyingparty/verifyPassword | F7: https://www.googleapis.com/identitytoolkit/v3/relyingparty/verifyPassword?key=AIzaSyDIM4lfYVaidv9qYmzRhvf5NPmgwQcU_4s | G7: { "email": "softwaredco@sunmobility.com", "password": "***REDACTED***", "returnSecureToken": true } | H7: 200 | J7: { "kind": "identitytoolkit#VerifyPasswordResponse", "localId": "1bwyuxWbg7ZbHhHJM4LXRPZ0WPw2", "email": "softwaredco@sunmobility.com", "displayName": "", "idToken": "***REDACTED***", "registered": true, "refreshToken": "***REDACTED***", "expiresIn": "3600" } | K7: 719
A8: 7 | B8: 2. Application › Applications grid loads with expected columns | C8: 2026-10-07 08:39:16.651 | D8: POST | E8: www.googleapis.com/identitytoolkit/v3/relyingparty/getAccountInfo | F8: https://www.googleapis.com/identitytoolkit/v3/relyingparty/getAccountInfo?key=AIzaSyDIM4lfYVaidv9qYmzRhvf5NPmgwQcU_4s | G8: { "idToken": "***REDACTED***" } | H8: 200 | J8: { "kind": "identitytoolkit#GetAccountInfoResponse", "users": [ { "localId": "1bwyuxWbg7ZbHhHJM4LXRPZ0WPw2", "email": "softwaredco@sunmobility.com", "passwordHash": "UkVEQUNURUQ=", "emailVerified": false, "passwordUpdatedAt": 1714840202414, "providerUserInfo": [ { "providerId": "password", "federatedId": "softwaredco@sunmobility.com", "email": "softwaredco@sunmobility.com", "rawId": "softwaredco@sunmobility.com" } ], "validSince": "1714840202", "disabled": false, "lastLoginAt": "1791362356356", "createdAt": "1714840202414", "lastRefreshAt": "2026-10-07T08:39:16.356Z" } ] } | K8: 633
A9: 8 | B9: 2. Application › Applications grid loads with expected columns | C9: 2026-10-07 08:39:17.291 | D9: POST | E9: smartnetwork.azure-api.net/smauth/api/v1/OAuth/ThirdPartyAuthentication | F9: https://smartnetwork.azure-api.net/smauth/api/v1/OAuth/ThirdPartyAuthentication | G9: { "email": "softwaredco@sunmobility.com", "password": "***REDACTED***", "returnSecureToken": true } | H9: 200 | I9: OK | J9: { "version": "1.0.0.0", "statusCode": 200, "message": "<JWT redacted>" } | K9: 698
A10: 9 | B10: 2. Application › Applications grid loads with expected columns | C10: 2026-10-07 08:39:17.994 | D10: GET | E10: smartnetwork.azure-api.net/partner-stage/api/v1/GetUserByEmail | F10: https://smartnetwork.azure-api.net/partner-stage/api/v1/GetUserByEmail?userEmail=softwaredco@sunmobility.com | H10: 200 | I10: OK | J10: { "status": 200, "data": { "userName": "RBAC Admin", "userEmail": "softwaredco@sunmobility.com", "userMobileNumber": "9845213813", "countryCode": "91", "userRole": "admin", "partnerId": "SUNMP00000121", "isActive": true, "isKeyFobMapped": false, "userId": "SUNMU00000370", "userType": "software", "createdAt": "1640240582", "lastModifiedAt": "1640240582", "createdUser": "Sun Mobility", "lastUpdatedUser": "Sun Mobility", "Key": "***REDACTED***", "legalEntityGuid": [ "c2b2bca1-019a-4757-ba37-9d9f5b30826a", "220c9382-d721-46db-9681-39bb9fff1511" ], "organizationName": "Sun Mobility Pvt Ltd", "brandName": "sun mobility" } } | K10: 3716
A11: 10 | B11: 2. Application › Applications grid loads with expected columns | C11: 2026-10-07 08:39:21.999 | D11: GET | E11: smartnetwork.azure-api.net/sm-rbac-provider-api-staging/api/v1/Application | F11: https://smartnetwork.azure-api.net/sm-rbac-provider-api-staging/api/v1/Application | H11: 200 | I11: OK | J11: { "version": "1.0.0.0", "statusCode": 200, "message": "Ok", "responseException": null, "result": [ { "applicationName": "abhistest", "applicationDescription": "asas", "applicationId": "e2121eb7-920b-478c-954f-e5f7693239be", "features": null, "pages": null, "createdBy": "RBAC Admin", "createdDate": "2026-10-04T16:44:25.224159", "modifiedDate": "2026-10-04T16:44:25.224159", "modifiedBy": "RBAC Admin", "isActive": true }, { "applicationName": "audit_app_2", "applicationDescription": "audit_app_2", "applicationId": "a59981dc-e912-4706-8efd-8a5fe158bf04", "features": "deletiontesting1 | deltiontesting", "pages": "5665 | deletiontesting | Testing", "createdBy": "RBAC Admin", "createdDate": "2025-01-15T10:01:04.161997", "modifiedDate": "2025-01-15T10:01:04.161997", "modifiedBy": "RBAC Admin", "isActive": true }, { "applicationName": "HEV_SERVICE", "applicationDescription": "HEV SERVICE APP", "applicationId": "1cd67ee7-c2c7-443e-9d7b-f1e6463200ef", "features": "ADMIN_PROVISION | ADMIN_USERLIST | ASSISTANCE_KEYFOB_READ | ASSISTANCE_BLE_UNLOCK_START | ASSISTANCE_KEYFOB_SEARCH | BATTERY_ISSUING_ONBOARDING | CUSTOMER_KEYFOB_READ | CUSTOMER_KEYFOB_SEARCH | CUSTOMER_PROVISION | KEYFOB_CHECK_READ | KEYFOB_CHECK_SEARCH | NOTIFICATION_FORCE_LOGOUT | NOTIFICATION_PUSH_NOTIFICATION | STATION_ASSESSMENT | STATION_CAN | TICKET_CREATE | TICKET_SUPPORT", "pages": "HEV_SERVICE_ADMIN | HEV_SERVICE_ASSISTANCE | HEV_SERVICE_BATTERY_ISSUING | HEV_SERVICE_CUSTOMER | HEV_SERVICE_KEYFOB_CHECK | HEV_SERVICE_NOTIFICATION | HEV_SERVICE_STATION_SCAN | HEV_SERVICE_TICKET", "createdBy": "RBAC Admin", "createdDate": "2026-09-29T14:06:51.91171", "modifiedDate": "2026-09-29T14:06:51.91171", "modifiedBy": "RBAC Admin", "isActive": true }, { "applicationName": "IB_Billing_Test", "applicationDescription": "IB_Billing_Test", "applicationId": "fdf88f12-9fc1-49fb-8250-5e1a6ccb95be", "features": "IB_Billing_App_login", "pages": "Vehicle_Transaction", "createdBy": "RBAC Admin", "createdDate": "2026-03-03T06:48:51.856422", "modifiedDate": "2026-03-03T06:48:51.856422", "modifiedBy": "RBAC Admin", "isActive": true }, { "applicationName": "INDOFAST_FLEET", "applicationDescription": "INDOFAST_FLEET", "applicationId": "3846ba37-5403-4187-aadd-f4500cc4f322", "features": "APP_MAIN | TestFeature | FLEET_LOGIN", "pages": "INDOFAST_FLEET_LAUNCH | INDOFAST_FLEET_LOGIN", "createdBy": "RBAC Admin", "createdDate": "2024-12-19T06:39:12.858721", "modifiedDate": "2024-12-19T06:39:12.858721", "modifiedBy": "RBAC Admin", "isActive": true }, { "applicationName": "INDOFAST_PARTNER", "applicationDescription": "INDOFAST_PARTNER", "applicationId": "48a32bc0-6e68-4719-8d4f-0c79746a174b", "features": "READ | SUBSCRIPTION_PLAN | INDOFAST_PARTNER_CHECK | SUBSCRIPTION_ACTIVATE | READ | abhishek_agent | FORCE_LOGOUT | PUSH_NOTIFICATION | SCAN_STATION | STATEMENT | rbac_feature | INDOFAST_PARTNER_SUBSCRIPTION_VIEW | TICKET_VEHICLE | TICKET_KEYFOB | TICKET_STATION | TICKET_BATTERY | CUSTOMER_KEYFOB_SEARCH | KEYFOB_SEARCH | CUSTOMER_SEARCH | CUSTOMER_PROVISION | KEYFOB_READ | REMOVE2 | WALLET_SEARCH | TRANSFER", "pages": "INDOFAST_PARTNER_KEYFOB_CHECK | INDOFAST_PARTNER_NOTIFICATION | INDOFAST_PARTNER_SCAN_STATION | INDOFAST_PARTNER_STATEMENT | INDOFAST_PARTNER_SUBSCRIPTION | INDOFAST_PARTNER_TICKET | INDOFAST_PARTNER_VEHICLE | INDOFAST_PARTNER_WALLET | Rbac_page", "createdBy": "RBAC Admin", "createdDate": "2024-11-15T04:58:47.127647", "modifiedDate": "2024-11-15T04:58:47.127647", "modifiedBy": "RBAC Admin", "isActive": true }, { "applicationName": "INDOFAST_RIDER", "applicationDescription": "INDOFAST_RIDER", "applicationId": "c883ee45-2524-4d07-933d-4df7581f4137", "features": "APP_MAIN | RIDER_LOGIN", "pages": "INDOFAST_RIDER_LAUNCH | INDOFAST_RIDER_LOGIN | RIDER_MAIN", "createdBy": "RBAC Admin", "createdDate": "2024-12-17T10:02:56.841694", "modifiedDate": "2024-12-17T10:02:56.841694", "modifiedBy": "RBAC Admin", "isActive": true }, { "applicationName": "INDOFAST_SERVICE", "applicationDescription": "INDOFAST_SERVICE", "applicationId": "8508504d-fb1c-4f47-bb87-b3277a34bdd9", "features": "ADMIN_PROVISION | ADMIN_USERLIST | ADMIN_USERLIST | ADMIN_PROVISION | SM_ADMIN | ASSISTANCE_KEYFOB_READ | ASSISTANCE_BLE_UNLOCK_START | ASSISTANCE_KEYFOB_READ | ASSISTANCE_KEYFOB_SEARCH | ASSISTANCE_BLE_UNLOCK_START | BATTERY_ISSUING_ONBOARDING | BP_ZONE_LOAD | BP_STATION_LOAD | BP_STATION_UNLOAD | BP_ZONE_UNLOAD | CUSTOMER_KEYFOB_SEARCH | CUSTOMER_KEYFOB_READ | CUSTOMER_PROVISION | SUBSCRIPTION_PLAN | KEYFOB_CHECK_READ | KEYFOB_CHECK_SEARCH | NOTIFICATION_PUSH_NOTIFICATION | NOTIFICATION_FORCE_LOGOUT | BP_ONBOARD | BP_OFFBOARD | STATION_UNLOAD | STATION_LOAD | STATION_ASSESSMENT | STATION_SCAN | TICKET_CREATE | TICKET_SUPPORT | service_tester | TestFeature1 | TestFeature2 | TestFeatures1 | TestFeatures2", "pages": "INDOFAST_SERVICE_ADMIN | INDOFAST_SERVICE_ASSISTANCE | INDOFAST_SERVICE_BATTERY_ISSUING | INDOFAST_SERVICE_BP_DASHBOARD | INDOFAST_SERVICE_CUSTOMER | INDOFAST_SERVICE_KEYFOB_CHECK | INDOFAST_SERVICE_NOTIFICATION | INDOFAST_SERVICE_ONBOARD_OFFBOARD_BP | INDOFAST_SERVICE_STATION_LOAD_UNLOAD | INDOFAST_SERVICE_STATION_SCAN | INDOFAST_SERVICE_TICKET | service_check | TestPage | TestPages", "createdBy": "RBAC Admin", "createdDate": "2024-11-14T09:38:16.27036", "modifiedDate": "2024-11-14T09:38:16.27036", "modifiedBy": "RBAC Admin", "isActive": true }, { "applicationName": "Indofast_service_app", "applicationDescription": "Indofast_service_app", "applicationId": "4916a491-549a-4093-b517-08a8fdc1dcb3", "features": null, "pages": null, "createdBy": "RBAC Admin", "createdDate": "2025-04-01T09:05:57.613231", "modifiedDate": "2025-04-01T09:05:57.613231", "modifiedBy": "RBAC Admin", "isActive": true }, { "applicationName": "INDOFAST_SERVICE_TESTING_APP", "applicationDescription": "INDOFAST_SERVICE_TESTING_APP", "applicationId": "03ac0b90-bb8d-4a8d-a6be-6b2780a372ce", "features": "INDOFAST_WRITE | INDOFAST_READ | INDOFAST_SEARCH", "pages": "INDOFAST_SERVICE_CHECK", "createdBy": "RBAC Admin", "createdDate": "2025-03-31T18:31:11.356646", "modifiedDate": "2025-03-31T18:31:11.356646", "modifiedBy": "RBAC Admin", "isActive": true }, { "applicationName": "INDOFAST_SWAPEASI", "applicationDescription": "INDOFAST_SWAPEASI APP", "applicationId": "1569662c-8193-4d54-882b-31c752a621d8", "features": "indofast_audit_3 | indofast_audit_2 | indofast_audit_3 | indofast_audit_log_4 | indofast_audit_4 | indofast_audit_log_1 | indofast_audit_log_4 | New_indofast_audit_log_2 | Sanjay_audit_3 | indofast_audit_log_3 | indofast_audit_log_4 | indofast_audit_log_3 | AUDIT_CHOOSE_DATE | AUDIT_CHOOSE_DATE | Indofast_audit_log | BP_LOAD | BP_ZONE_UNLOAD | BP_ZONE_LOAD | BP_UNLOAD | CHOOSE_VIN_SELECT_VEHICLE | CHOOSE_VIN_SEARCH_VEHICLE | CHOOSE_VIN_SCAN_VEHICLE | CUSTOMER_SCAN_VEHICLE | CUSTOMER_BATTERY_SWAP | CUSTOMER_BLE_UNLOCK | CUSTOMER_SEARCH | SUBSCRIPTION_PLAN | SUBSCRIPTION_ACTIVATE | CUSTOMER_TAP_KEYFOB | DASHBOARD_CHANGE_VEHICLE | FIELD_SCAN_STATION | FIELD_SEARCH_STATION | FIELD_LOAD_EMPTY_BATTERY | FIELD_EXCHANGE_BATTERY | FIELD_UNLOAD_FULL_BATTERY | BP_OFFBOARD | BP_ONBOARD | STATION_SCAN | SERVICE_LOAD_FULL_BATTERY | SERVICE_UNLOAD_EMPTY_BATTERY | SERVICE_SCAN_STATION | SERVICE_EXCHANGE_BATTERY | SERVICE_SEARCH_STATION | New_indofast_audit_log_2 | New_indofast_audit_log_1 | Sanjay_audit_2 | Sanjay_audit_3 | Sanjay_audit_1 | SM_ESV_APPROVALS_VIEW | ASSISTANCE_BLE_UNLOCK_START | ASSISTANCE_KEYFOB_SEARCH | ASSISTANCE_KEYFOB_READ | BATTERY_ISSUING_ONBOARDING | SM_ESV_BP_REQUESTS_VIEW | SM_ESV_STATION_SCAN | SM_ESV_STATION_LOAD_DRAINED_BP | SM_ESV_STATION_EXCHANGE_BP | SM_ESV_STATION_SEARCH | SM_ESV_STATION_LOAD_FULL_BP | SM_ESV_STATION_UNLOAD_DRAINED_BP | SM_ESV_STATION_UNLOAD_FULL_BP | SM_ESV_STORE_DASHBOARD_VIEW | SM_ESV_STORE_LISTING_FEATURE | SM_ESV_STORE_TRANSIT_VIEW", "pages": "AUDIT_CHOOSE_DATE | indofast_audit_1 | Indofast_audit_log | indofast_audit_log_1 | indofast_audit_log_2 | INDOFAST_SWAPEASI_AUDIT | INDOFAST_SWAPEASI_BP_DASHBOARD | INDOFAST_SWAPEASI_CHOOSE_VIN | INDOFAST_SWAPEASI_CUSTOMER | INDOFAST_SWAPEASI_DASHBOARD | INDOFAST_SWAPEASI_FIELD | INDOFAST_SWAPEASI_ONBOARD_OFFBOARD_BP | INDOFAST_SWAPEASI_SCAN_STATION | INDOFAST_SWAPEASI_SERVICE | Indofast_swap_easy_auditlog | New_indofast_audit_log | Sanjay_audit | SM_ESV_APPROVALS | SM_ESV_ASSISTANCE | SM_ESV_AUDIT | SM_ESV_BATTERY_ISSUING | SM_ESV_BP_DASHBOARD | SM_ESV_BP_REQUESTS | SM_ESV_CHOOSE_VIN | SM_ESV_CUSTOMER | SM_ESV_DASHBOARD | SM_ESV_FIELD | SM_ESV_SCAN_STATION | SM_ESV_SERVICE | SM_ESV_STATION | SM_ESV_STORE_DASHBOARD | SM_ESV_STORE_LISTING | SM_ESV_STORE_TRANSIT | Test", "createdBy": "RBAC Admin", "createdDate": "2024-11-15T04:45:12.337869", "modifiedDate": "2024-12-09T07:22:21.123754", "modifiedBy": "RBAC Admin", "isActive": true }, { "applicationName": "Indofast Test App ${Date.now()}", "applicationDescription": "Indofast Test Service App ${Date.now()}", "applicationId": "1af51c4a-ee35-4c34-b151-dfc6e0e497df", "features": null, "pages": null, "createdBy": "RBAC Admin", "createdDate": "2026-09-29T16:03:36.459777", "modifiedDate": "2026-09-29T16:03:36.459777", "modifiedBy": "RBAC Admin", "isActive": true }, { "applicationName": "Indofast Test App ${runId}", "applicationDescription": "Indofast Test Service App ${runId}", "applicationId": "fc4a23fc-db90-434d-9e83-4bc4f0d9e9b8", "features": null, "pages": null, "createdBy": "RBAC Admin", "createdDate": "2026-09-29T15:59:36.2416", "modifiedDate": "2026-09-29T15:59:36.2416", "modifiedBy": "RBAC Admin", "isActive": true }, { "applicationName": "Indofast Test App 1790698304735", "applicationDescription": "Indofast Test Service App 1790698304735", "applicationId": "c760affb-819d-4fb9-9a91-e7c046561a2a", "features": null, "pages": null, "createdBy": "RBAC Admin", "createdDate": "2026-09-29T16:12:04.319722", "modifiedDate": "2026-09-29T16:12:04.319722", "modifiedBy": "RBAC Admin", "isActive": true }, { "applicationName": "Indofast Test App 1790698632790", "applicationDescription": "Indofast Test Service App 1790698632790", "applicationId": "9d74bd47-98c9-47bf-bc29-f5bfeae24139", "features": null, "pages": null, "createdBy": "RBAC Admin", "createdDate": "2026-09-29T16:17:34.564874", "modifiedDate": "2026-09-29T16:17:34.564874", "modifiedBy": "RBAC Admin", "isActive": true }, { "applicationName": "Indofast Test App 1790705334620", "applicationDescription": "Indofast Test Service App 1790705334620", "applicationId": "925ae917-d77c-466c-aa6f-24b437f0e352", "features": null, "pages": null, "createdBy": "RBAC Admin", "createdDate": "2026-09-29T18:09:22.868203", "modifiedDate": "2026-09-29T18:09:22.868203", "modifiedBy": "RBAC Admin", "isActive": true }, { "applicationName": "Indofast Test App 1790705407619", "applicationDescription": "Indofast Test Service App 1790705407619", "applicationId": "b7d5b91c-d750-4c16-b173-8741680173da", "features": null, "pages": null, "createdBy": "RBAC Admin", "createdDate": "2026-09-29T18:10:52.005696", "modifiedDate": "2026-09-29T18:10:52.005696", "modifiedBy": "RBAC Admin", "isActive": true }, { "applicationName": "Indofast Test App 1790705554802", "applicationDescription": "Indofast Test Service App 1790705554802", "applicationId": "a38a0f8d-bde9-46d1-89d0-61a7c0d2299e", "features": null, "pages": null, "createdBy": "RBAC Admin", "createdDate": "2026-09-29T18:13:06.834697", "modifiedDate": "2026-09-29T18:13:06.834697", "modifiedBy": "RBAC Admin", "isActive": true }, { "applicationName": "Indofast Test App 1790705674815", "applicationDescription": "Indofast Test Service App 1790705674815", "applicationId": "d75814d5-5e12-491a-9d16-72830f76b821", "features": null, "pages": null, "createdBy": "RBAC Admin", "createdDate": "2026-09-29T18:15:02.553628", "modifiedDate": "2026-09-29T18:15:02.553628", "modifiedBy": "RBAC Admin", "isActive": true }, { "applicationName": "Indofast Test App 1790705820113", "applicationDescription": "Indofast Test Service App 1790705820113", "applicationId": "f5eecf83-2b86-4c71-a77e-6b2c97b10ac6", "features": null, "pages": null, "createdBy": "RBAC Admin", "createdDate": "2026-09-29T18:17:19.202134", "modifiedDate": "2026-09-29T18:17:19.202134", "modifiedBy": "RBAC Admin", "isActive": true }, { "applicationName": "Indofast Test App 1790706474318", "applicationDescription": "Indofast Test Service App 1790706474318", "applicationId": "4311249c-8361-47a6-8fbc-d5fdd86a2725", "features": null, "pages": null, "createdBy": "RBAC Admin", "createdDate": "2026-09-29T18:28:20.733757", "modifiedDate": "2026-09-29T18:28:20.733757", "modifiedBy": "RBAC Admin", "isActive": true }, { "applicationName": "Indofast Test App 1790706561663", "applicationDescription": "Indofast Test Service App 1790706561663", "applicationId": "10f34dae-8dd2-469e-8d17-87e0b9640e6b", "features": null, "pages": null, "createdBy": "RBAC Admin", "createdDate": "2026-09-29T18:29:46.047325", "modifiedDate": "2026-09-29T18:29:46.047325", "modifiedBy": "RBAC Admin", "isActive": true }, { "applicationName": "Indofast Test App 1790706673911", "applicationDescription": "Indofast Test Service App 1790706673911", "applicationId": "6838751e-6f90-4607-9bd2-39b03e1358cf", "features": null, "pages": null, "createdBy": "RBAC Admin", "createdDate": "2026-09-29T18:31:47.029861", "modifiedDate": "2026-09-29T18:31:47.029861", "modifiedBy": "RBAC Admin", "isActive": true }, { "applicationName": "Indofast Test App 1790706982926", "applicationDescription": "Indofast Test Service App 1790706982926", "applicationId": "2c65fcee-88eb-4d87-b3be-51cc9f5d01b9", "features": null, "pages": null, "createdBy": "RBAC Admin", "createdDate": "2026-09-29T18:36:52.615532", "modifiedDate": "2026-09-29T18:36:52.615532", "modifiedBy": "RBAC Admin", "isActive": true }, { "applicationName": "Indofast Test App 1790707143851", "applicationDescription": "Indofast Test Service App 1790707143851", "applicationId": "41251a45-f0a5-4102-bdee-081976f01111", "features": null, "pages": null, "createdBy": "RBAC Admin", "createdDate": "2026-09-29T18:39:27.941236", "modifiedDate": "2026-09-29T18:39:27.941236", "modifiedBy": "RBAC Admin", "isActive": true }, { "applicationName": "Indofast Test App 1790707209323", "applicationDescription": "Indofast Test Service App 1790707209323", "applicationId": "9e20d9fc-284a-42eb-a7a9-704ed9d312dc", "features": null, "pages": null, "createdBy": "RBAC Admin", "createdDate": "2026-09-29T18:40:34.846498", "modifiedDate": "2026-09-29T18:40:34.846498", "modifiedBy": "RBAC Admin", "isActive": true }, { "applicationName": "Indofast Test App 1790707359316", "applicationDescription": "Indofast Test Service App 1790707359316", "applicationId": "2dfa65c7-b0e4-427d-b070-5679584f050b", "features": null, "pages": "Indofast dashboard page 1790707359316", "createdBy": "RBAC Admin", "createdDate": "2026-09-29T18:42:59.455979", "modifiedDate": "2026-09-29T18:42:59.455979", "modifiedBy": "RBAC Admin", "isActive": true }, { "applicationName": "Indofast Test App 1790960475078", "applicationDescription": "Indofast Test Service App 1790960475078", "applicationId": "a64c536e-2afc-4655-b415-bc891c53f396", "features": null, "pages": "Indofast dashboard page 1790960475078", "createdBy": "RBAC Admin", "createdDate": "2026-10-02T17:02:38.832152", "modifiedDate": "2026-10-02T17:02:38.832152", "modifiedBy": "RBAC Admin", "isActive": true }, { "applicationName": "Indofast Test App 1790961594486", "applicationDescription": "Indofast Test Service App 1790961594486", "applicationId": "1b69f623-e749-47dd-8792-c938373b7cf6", "features": null, "pages": "Indofast dashboard page 1790961594486", "createdBy": "RBAC Admin", "createdDate": "2026-10-02T17:21:09.820675", "modifiedDate": "2026-10-02T17:21:09.820675", "modifiedBy": "RBAC Admin", "isActive": true }, { "applicationName": "Indofast Test App 1790961885381", "applicationDescription": "Indofast Test Service App 1790961885381", "applicationId": "146d33f1-8e0f-4a1c-a4c0-7bd046f10c93", "features": null, "pages": "Indofast dashboard page 1790961885381", "createdBy": "RBAC Admin", "createdDate": "2026-10-02T17:26:33.588429", "modifiedDate": "2026-10-02T17:26:33.588429", "modifiedBy": "RBAC Admin", "isActive": true }, { "applicationName": "Indofast Test App 1790962157265", "applicationDescription": "Indofast Test Service App 1790962157265", "applicationId": "0749f8c9-d98b-4ceb-8c3f-85db7aa6a20f", "features": null, "pages": "Indofast dashboard page 1790962157265", "createdBy": "RBAC Admin", "createdDate": "2026-10-02T17:30:32.89161", "modifiedDate": "2026-10-02T17:30:32.89161", "modifiedBy": "RBAC Admin", "isActive": true }, { "applicationName": "Indofast Test App 1790962334356", "applicationDescription": "Indofast Test Service App 1790962334356", "applicationId": "8ece8dbd-64fd-4884-9ac4-fc42aae26965", "features": null, "pages": "Indofast dashboard page 1790962334356", "createdBy": "RBAC Admin", "createdDate": "2026-10-02T17:33:38.535086", "modifiedDate": "2026-10-02T17:33:38.535086", "modifiedBy": "RBAC Admin", "isActive": true }, { "applicationName": "Indofast Test App 1790962487871", "applicationDescription": "Indofast Test Service App 1790962487871", "applicationId": "dde5b72c-bca7-4ac5-9720-6199a5cd8fcb", "features": "checkpage 1790962487871", "pages": "Indofast dashboard page 1790962487871", "createdBy": "RBAC Admin", "createdDate": "2026-10-02T17:35:42.524463", "modifiedDate": "2026-10-02T17:35:42.524463", "modifiedBy": "RBAC Admin", "isActive": true }, { "applicationName": "Indofast Test App 1790964323999", "applicationDescription": "Indofast Test Service App 1790964323999", "applicationId": "a65f767a-7188-4068-9743-f57116dc824e", "features": "checkpage 1790964323999", "pages": "Indofast dashboard page 1790964323999", "createdBy": "RBAC Admin", "createdDate": "2026-10-02T18:06:39.157025", "modifiedDate": "2026-10-02T18:06:39.157025", "modifiedBy": "RBAC Admin", "isActive": true }, { "applicationName": "Indofast Test App 1790964696233", "applicationDescription": "Indofast Test Service App 1790964696233", "applicationId": "61333ee9-9684-4a7e-8b04-471811f61869", "features": "checkpage 1790964696233", "pages": "Indofast dashboard page 1790964696233", "createdBy": "RBAC Admin", "createdDate": "2026-10-02T18:13:01.546738", "modifiedDate": "2026-10-02T18:13:01.546738", "modifiedBy": "RBAC Admin", "isActive": true }, { "applicationName": "Indofast Test App 1790965235365", "applicationDescription": "Indofast Test Service App 1790965235365", "applicationId": "74607b10-c3f8-4ca2-809f-95cf066f0198", "features": "checkpage 1790965235365", "pages": "Indofast dashboard page 1790965235365", "createdBy": "RBAC Admin", "createdDate": "2026-10-02T18:21:48.71923", "modifiedDate": "2026-10-02T18:21:48.71923", "modifiedBy": "RBAC Admin", "isActive": true }, { "applicationName": "Indofast Test App 1790965561618", "applicationDescription": "Indofast Test Service App 1790965561618", "applicationId": "2d2756ed-f5b6-49e3-b717-c5c6e3148273", "features": "checkpage 1790965561618", "pages": "Indofast dashboard page 1790965561618", "createdBy": "RBAC Admin", "createdDate": "2026-10-02T18:27:17.6897", "modifiedDate": "2026-10-02T18:27:17.6897", "modifiedBy": "RBAC Admin", "isActive": true }, { "applicationName": "Indofast Test App 1791022693333", "applicationDescription": "Indofast Test Service App 1791022693333", "applicationId": "8219f221-b301-4201-8341-ac1175f13dc0", "features": null, "pages": "Indofast dashboard page 1791022693333", "createdBy": "RBAC Admin", "createdDate": "2026-10-03T10:20:00.750165", "modifiedDate": "2026-10-03T10:20:00.750165", "modifiedBy": "RBAC Admin", "isActive": true }, { "applicationName": "Indofast Test App 1791044152955", "applicationDescription": "Indofast Test Service App 1791044152955", "applicationId": "ec275f2a-2221-42c4-9328-fd6b0f50b882", "features": "checkpage 1791044152955", "pages": "Indofast dashboard page 1791044152955", "createdBy": "RBAC Admin", "createdDate": "2026-10-03T16:17:16.741596", "modifiedDate": "2026-10-03T16:17:16.741596", "modifiedBy": "RBAC Admin", "isActive": true }, { "applicationName": "Indofast Test App 1791044544096", "applicationDescription": "Indofast Test Service App 1791044544096", "applicationId": "18612c0d-dfba-456d-b1a7-a58c7f13fdd8", "features": null, "pages": "Indofast dashboard page 1791044544096", "createdBy": "RBAC Admin", "createdDate": "2026-10-03T16:23:04.584413", "modifiedDate": "2026-10-03T16:23:04.584413", "modifiedBy": "RBAC Admin", "isActive": true }, { "applicationName": "Indofast Test App 1791044666980", "applicationDescription": "Indofast Test Service App 1791044666980", "applicationId": "09bbcc1d-142c-48ec-ae1c-a78042d4f8a3", "features": "checkpage 1791044666980", "pages": "Indofast dashboard page 1791044666980", "createdBy": "RBAC Admin", "createdDate": "2026-10-03T16:25:05.333966", "modifiedDate": "2026-10-03T16:25:05.333966", "modifiedBy": "RBAC Admin", "isActive": true }, { "applicationName": "Indofast Test App 1791044816519", "applicationDescription": "Indofast Test Service App 1791044816519", "applicationId": "c85e87d7-4565-4e49-a096-fb564202829a", "features": "checkpage 1791044816519", "pages": "Indofast dashboard page 1791044816519", "createdBy": "RBAC Admin", "createdDate": "2026-10-03T16:27:32.684583", "modifiedDate": "2026-10-03T16:27:32.684583", "modifiedBy": "RBAC Admin", "isActive": true }, { "applicationName": "Indofast Test App 1791045003864", "applicationDescription": "Indofast Test Service App 1791045003864", "applicationId": "e0ac5c75-0648-49e3-b13a-9473c476fefd", "features": "checkpage 1791045003864", "pages": "Indofast dashboard page 1791045003864", "createdBy": "RBAC Admin", "createdDate": "2026-10-03T16:30:42.333395", "modifiedDate": "2026-10-03T16:30:42.333395", "modifiedBy": "RBAC Admin", "isActive": true }, { "applicationName": "Indofast Test App 1791045109438", "applicationDescription": "Indofast Test Service App 1791045109438", "applicationId": "72db0f49-cc6e-44b0-bc99-2cad9536754b", "features": "checkpage 1791045109438", "pages": "Indofast dashboard page 1791045109438", "createdBy": "RBAC Admin", "createdDate": "2026-10-03T16:32:22.121882", "modifiedDate": "2026-10-03T16:32:22.121882", "modifiedBy": "RBAC Admin", "isActive": true }, { "applicationName": "Indofast Test App 1791045194378", "applicationDescription": "Indofast Test Service App 1791045194378", "applicationId": "293e6464-5255-4dfd-9241-73b720a59d29", "features": "checkpage 1791045194378", "pages": "Indofast dashboard page 1791045194378", "createdBy": "RBAC Admin", "createdDate": "2026-10-03T16:33:42.826353", "modifiedDate": "2026-10-03T16:33:42.826353", "modifiedBy": "RBAC Admin", "isActive": true }, { "applicationName": "Indofast Test App 1791045346133", "applicationDescription": "Indofast Test Service App 1791045346133", "applicationId": "768c0198-c896-4f69-8819-2b4821741830", "features": "checkpage 1791045346133", "pages": "Indofast dashboard page 1791045346133", "createdBy": "RBAC Admin", "createdDate": "2026-10-03T16:36:16.888272", "modifiedDate": "2026-10-03T16:36:16.888272", "modifiedBy": "RBAC Admin", "isActive": true }, { "applicationName": "Indofast Test App 1791045507223", "applicationDescription": "Indofast Test Service App 1791045507223", "applicationId": "7cb3aa33-a621-4bc3-85f1-7fa52eaaa63e", "features": "checkpage 1791045507223", "pages": "Indofast dashboard page 1791045507223", "createdBy": "RBAC Admin", "createdDate": "2026-10-03T16:38:55.630794", "modifiedDate": "2026-10-03T16:38:55.630794", "modifiedBy": "RBAC Admin", "isActive": true }, { "applicationName": "Indofast Test App 1791045620366", "applicationDescription": "Indofast Test Service App 1791045620366", "applicationId": "76b2033f-e9de-41ae-986b-0dda65a8424d", "features": "checkpage 1791045620366", "pages": "Indofast dashboard page 1791045620366", "createdBy": "RBAC Admin", "createdDate": "2026-10-03T16:40:49.296577", "modifiedDate": "2026-10-03T16:40:49.296577", "modifiedBy": "RBAC Admin", "isActive": true }, { "applicationName": "Indofast Test App 1791045740130", "applicationDescription": "Indofast Test Service App 1791045740130", "applicationId": "d2c9b12d-0e49-4253-802d-a0c9cd07c4b4", "features": "checkpage 1791045740130", "pages": "Indofast dashboard page 1791045740130", "createdBy": "RBAC Admin", "createdDate": "2026-10-03T16:42:54.565128", "modifiedDate": "2026-10-03T16:42:54.565128", "modifiedBy": "RBAC Admin", "isActive": true }, { "applicationName": "Indofast Test App 1791045933527", "applicationDescription": "Indofast Test Service App 1791045933527", "applicationId": "c3bd03df-7b16-45f8-953a-edaae0329616", "features": "checkpage 1791045933527", "pages": "Indofast dashboard page 1791045933527", "createdBy": "RBAC Admin", "createdDate": "2026-10-03T16:46:46.959699", "modifiedDate": "2026-10-03T16:46:46.959699", "modifiedBy": "RBAC Admin", "isActive": true }, { "applicationName": "Indofast Test App 1791046283484", "applicationDescription": "Indofast Test Service App 1791046283484", "applicationId": "49705227-d356-4cbc-bf71-689854e067ac", "features": "checkpage 1791046283484", "pages": "Indofast dashboard page 1791046283484", "createdBy": "RBAC Admin", "createdDate": "2026-10-03T16:52:48.751906", "modifiedDate": "2026-10-03T16:52:48.751906", "modifiedBy": "RBAC Admin", "isActive": true }, { "applicationName": "Indofast Test App 1791046674503", "applicationDescription": "Indofast Test Service App 1791046674503", "applicationId": "ea197311-050e-4e37-a8be-0e72d6fb9b23", "features": "checkpage 1791046674503", "pages": "Indofast dashboard page 1791046674503", "createdBy": "RBAC Admin", "createdDate": "2026-10-03T16:58:23.66034", "modifiedDate": "2026-10-03T16:58:23.66034", "modifiedBy": "RBAC Admin", "isActive": true }, { "applicationName": "Indofast Test App 1791046889687", "applicationDescription": "Indofast Test Service App 1791046889687", "applicationId": "35a14b2e-8141-44a7-b688-55a2fa4f01fc", "features": "checkpage 1791046889687", "pages": "Indofast dashboard page 1791046889687", "createdBy": "RBAC Admin", "createdDate": "2026-10-03T17:02:00.561981", "modifiedDate": "2026-10-03T17:02:00.561981", "modifiedBy": "RBAC Admin", "isActive": true }, { "applicationName": "Indofast Test App 1791047060907", "applicationDescription": "Indofast Test Service App 1791047060907", "applicationId": "9c5999c3-5de1-4e82-a607-12b37586037c", "features": "checkpage 1791047060907", "pages": "Indofast dashboard page 1791047060907", "createdBy": "RBAC Admin", "createdDate": "2026-10-03T17:04:50.505576", "modifiedDate": "2026-10-03T17:04:50.505576", "modifiedBy": "RBAC Admin", "isActive": true }, { "applicationName": "Indofast Test App 1791047818359", "applicationDescription": "Indofast Test Service App 1791047818359", "applicationId": "ae2e3aae-835c-4997-9c1a-81c9b71c1af5", "features": "checkpage 1791047818359", "pages": "Indofast dashboard page 1791047818359", "createdBy": "RBAC Admin", "createdDate": "2026-10-03T17:17:29.649882", "modifiedDate": "2026-10-03T17:17:29.649882", "modifiedBy": "RBAC Admin", "isActive": true }, { "applicationName": "Indofast Test App 1791047961007", "applicationDescription": "Indofast Test Service App 1791047961007", "applicationId": "53eb8b3b-6048-4737-8d46-c5e532c3a82d", "features": "checkpage 1791047961007", "pages": "Indofast dashboard page 1791047961007", "createdBy": "RBAC Admin", "createdDate": "2026-10-03T17:19:54.343104", "modifiedDate": "2026-10-03T17:19:54.343104", "modifiedBy": "RBAC Admin", "isActive": true }, { "applicationName": "Indofast Test App 1791048214768", "applicationDescription": "Indofast Test Service App 1791048214768", "applicationId": "cfa86488-47ee-4891-937d-cd30301b743a", "features": "checkpage 1791048214768", "pages": "Indofast dashboard page 1791048214768", "createdBy": "RBAC Admin", "createdDate": "2026-10-03T17:24:03.67266", "modifiedDate": "2026-10-03T17:24:03.67266", "modifiedBy": "RBAC Admin", "isActive": true }, { "applicationName": "Indofast Test App 1791048415950", "applicationDescription": "Indofast Test Service App 1791048415950", "applicationId": "99b8102f-7101-4d2b-aff9-73d980693366", "features": "checkpage 1791048415950", "pages": "Indofast dashboard p ... [truncated, 68711 chars total] | K11: 3405
A12: 11 | B12: 2. Application › Add application | C12: 2026-10-07 08:39:31.724 | D12: POST | E12: www.googleapis.com/identitytoolkit/v3/relyingparty/verifyPassword | F12: https://www.googleapis.com/identitytoolkit/v3/relyingparty/verifyPassword?key=AIzaSyDIM4lfYVaidv9qYmzRhvf5NPmgwQcU_4s | G12: { "email": "softwaredco@sunmobility.com", "password": "***REDACTED***", "returnSecureToken": true } | H12: 200 | J12: { "kind": "identitytoolkit#VerifyPasswordResponse", "localId": "1bwyuxWbg7ZbHhHJM4LXRPZ0WPw2", "email": "softwaredco@sunmobility.com", "displayName": "", "idToken": "***REDACTED***", "registered": true, "refreshToken": "***REDACTED***", "expiresIn": "3600" } | K12: 582
A13: 12 | B13: 2. Application › Add application | C13: 2026-10-07 08:39:32.316 | D13: POST | E13: www.googleapis.com/identitytoolkit/v3/relyingparty/getAccountInfo | F13: https://www.googleapis.com/identitytoolkit/v3/relyingparty/getAccountInfo?key=AIzaSyDIM4lfYVaidv9qYmzRhvf5NPmgwQcU_4s | G13: { "idToken": "***REDACTED***" } | H13: 200 | J13: { "kind": "identitytoolkit#GetAccountInfoResponse", "users": [ { "localId": "1bwyuxWbg7ZbHhHJM4LXRPZ0WPw2", "email": "softwaredco@sunmobility.com", "passwordHash": "UkVEQUNURUQ=", "emailVerified": false, "passwordUpdatedAt": 1714840202414, "providerUserInfo": [ { "providerId": "password", "federatedId": "softwaredco@sunmobility.com", "email": "softwaredco@sunmobility.com", "rawId": "softwaredco@sunmobility.com" } ], "validSince": "1714840202", "disabled": false, "lastLoginAt": "1791362356356", "createdAt": "1714840202414", "lastRefreshAt": "2026-10-07T08:39:16.356Z" } ] } | K13: 561
A14: 13 | B14: 2. Application › Add application | C14: 2026-10-07 08:39:32.885 | D14: POST | E14: smartnetwork.azure-api.net/smauth/api/v1/OAuth/ThirdPartyAuthentication | F14: https://smartnetwork.azure-api.net/smauth/api/v1/OAuth/ThirdPartyAuthentication | G14: { "email": "softwaredco@sunmobility.com", "password": "***REDACTED***", "returnSecureToken": true } | H14: 200 | I14: OK | J14: { "version": "1.0.0.0", "statusCode": 200, "message": "<JWT redacted>" } | K14: 555
A15: 14 | B15: 2. Application › Add application | C15: 2026-10-07 08:39:33.445 | D15: GET | E15: smartnetwork.azure-api.net/partner-stage/api/v1/GetUserByEmail | F15: https://smartnetwork.azure-api.net/partner-stage/api/v1/GetUserByEmail?userEmail=softwaredco@sunmobility.com | H15: 200 | I15: OK | J15: { "status": 200, "data": { "userName": "RBAC Admin", "userEmail": "softwaredco@sunmobility.com", "userMobileNumber": "9845213813", "countryCode": "91", "userRole": "admin", "partnerId": "SUNMP00000121", "isActive": true, "isKeyFobMapped": false, "userId": "SUNMU00000370", "userType": "software", "createdAt": "1640240582", "lastModifiedAt": "1640240582", "createdUser": "Sun Mobility", "lastUpdatedUser": "Sun Mobility", "Key": "***REDACTED***", "legalEntityGuid": [ "c2b2bca1-019a-4757-ba37-9d9f5b30826a", "220c9382-d721-46db-9681-39bb9fff1511" ], "organizationName": "Sun Mobility Pvt Ltd", "brandName": "sun mobility" } } | K15: 116
